# Question

Is this function safe? Why or why not?

```js
const getUser = async (userId) => {
  const url = `https://jsonplaceholder.typicode.com/users/${userId}`;
  const response = await fetch(url);
  const users = await response.json();
  console.log(users)
  return users;
}
getUser(-1)
```

Again, running the code gives you the answer, so try to figure it out on your own first!

# Answer
This function is not safe because in this situation, a userID that is not existent will throw a 404 error. It is best to practice the try and catch. An example is shwon below

```jsx
const getUser = async (userId) => {
  try {
    const url = `https://jsonplaceholder.typicode.com/users/${userId}`;
    const response = await fetch(url);

    if (!response.ok) {
      throw new Error(`HTTP error! Status: ${response.status}`);
      // throws new error with response status if there was an error
    }

    const user = await response.json();
    console.log(user);
    return user;
  } catch (error) {
    console.error('Error fetching user:', error.message);
    throw error; 
  }
};
```

# Teacher Feedback
Nice!
Score: 3/3